Workbook

Sheet Wine Inventory
A1: Wine ID | B1: Wine Name | C1: Producer | D1: Country of Origin | E1: Region | F1: Vintage | G1: Wine Style | H1: Grape Variety | I1: Alcohol % | J1: Sweetness | K1: Acidity | L1: Tannins | M1: Body | N1: Tasting Notes | O1: Food Pairing | P1: Retail Price (NZD) | Q1: Wholesale Cost (NZD) | R1: Gross Margin % | S1: Stock Quantity | T1: Reorder Level | U1: Inventory Value (NZD) | V1: Availability | W1: Supplier | X1: Customer Rating / 5 | Y1: Organic | Z1: Bottle Size (mL) | AA1: Closure | AB1: Serving Temperature (°C) | AC1: Drink From | AD1: Drink Until
A2: W-0001 | B2: Crimson Cove 001 | C2: Silver Fern Cellars | D2: China | E2: Veneto | F2: 2001 | G2: Red | H2: Sangiovese | I2: 10.5 | J2: Dry | K2: Low | L2: Low | M2: Full | N2: black pepper, dark chocolate | O2: roast lamb | P2: 131.94 | Q2: 79.59 | R2: =IFERROR((P2-Q2)/P2,0) -> 0.39677126 | S2: 96 | T2: 50 | U2: =P2*S2 -> 12666.24 | V2: In Stock | W2: Estate Direct | X2: 3.6 | Y2: No | Z2: 750 | AA2: Cork | AB2: 18 | AC2: 2028 | AD2: 2041
A3: W-0002 | B3: Starlit Passage 002 | C3: Bellwether Vineyards | D3: South Korea | E3: Alsace | F3: 2003 | G3: Red | H3: Malbec | I3: 11.4 | J3: Dry | K3: High | L3: High | M3: Full | N3: tobacco, cedar | O3: mushroom risotto | P3: 141.26 | Q3: 82.16 | R3: =IFERROR((P3-Q3)/P3,0) -> 0.41837746 | S3: 350 | T3: 12 | U3: =P3*S3 -> 49441 | V3: In Stock | W3: Southern Wine Supply | X3: 3.9 | Y3: No | Z3: 750 | AA3: Cork | AB3: 12 | AC3: 2021 | AD3: 2035
A4: W-0003 | B4: Misty Horizon 003 | C4: Quiet Lantern Estate | D4: Montenegro | E4: Alentejo | F4: 2020 | G4: Red | H4: Nebbiolo | I4: 15.4 | J4: Dry | K4: Medium | L4: Medium | M4: Full | N4: black pepper, raspberry | O4: mushroom risotto | P4: 21.28 | Q4: 11.43 | R4: =IFERROR((P4-Q4)/P4,0) -> 0.46287594 | S4: 600 | T4: 50 | U4: =P4*S4 -> 12768 | V4: In Stock | W4: Southern Wine Supply | X4: 4.9 | Y4: No | Z4: 750 | AA4: Synthetic cork | AB4: 18 | AC4: 2025 | AD4: 2029
A5: W-0004 | B5: Crescent Terrace 004 | C5: Bellwether Vineyards | D5: Jordan | E5: Sicily | F5: 2013 | G5: Rosé | H5: Syrah | I5: 12.4 | J5: Dry | K5: High | L5: Low | M5: Light | N5: rose petal, strawberry | O5: charcuterie | P5: 30.11 | Q5: 13.15 | R5: =IFERROR((P5-Q5)/P5,0) -> 0.56326802 | S5: 1 | T5: 12 | U5: =P5*S5 -> 30.11 | V5: In Stock | W5: Vine Trade NZ | X5: 3.3 | Y5: Yes | Z5: 1500 | AA5: Cork | AB5: 14 | AC5: 2027 | AD5: 2030
A6: W-0005 | B6: Wild Willow 005 | C6: Crown & Root Cellars | D6: Armenia | E6: Champagne | F6: 2010 | G6: Red | H6: Syrah | I6: 10.7 | J6: Dry | K6: High | L6: Low | M6: Full | N6: cedar, plum | O6: roast lamb | P6: 51.57 | Q6: 26.49 | R6: =IFERROR((P6-Q6)/P6,0) -> 0.48632926 | S6: 12 | T6: 12 | U6: =P6*S6 -> 618.84 | V6: Backorder | W6: Estate Direct | X6: 4.1 | Y6: No | Z6: 750 | AA6: Synthetic cork | AB6: 10 | AC6: 2022 | AD6: 2031
A7: W-0006 | B7: Frosted Summit 006 | C7: Quiet Lantern Estate | D7: Uganda | E7: Alsace | F7: 2025 | G7: Rosé | H7: Pinot Noir | I7: 12.2 | J7: Off-dry | K7: Low | L7: Low | M7: Light | N7: strawberry, rose petal | O7: grilled prawns | P7: 1228.79 | Q7: 644.81 | R7: =IFERROR((P7-Q7)/P7,0) -> 0.47524801 | S7: 0 | T7: 12 | U7: =P7*S7 -> 0 | V7: Out of Stock | W7: Southern Wine Supply | X7: 4 | Y7: Yes | Z7: 750 | AA7: Screw cap | AB7: 14 | AC7: 2021 | AD7: 2025
A8: W-0007 | B8: Scarlet Falcon 007 | C8: Bellwether Vineyards | D8: Ecuador | E8: Champagne | F8: 1999 | G8: White | H8: Viognier | I8: 15.4 | J8: Dry | K8: Medium | L8: Low | M8: Medium | N8: green apple, lime | O8: grilled fish | P8: 64.35 | Q8: 32.01 | R8: =IFERROR((P8-Q8)/P8,0) -> 0.5025641 | S8: 200 | T8: 24 | U8: =P8*S8 -> 12870 | V8: In Stock | W8: Southern Wine Supply | X8: 3.8 | Y8: Yes | Z8: 750 | AA8: Synthetic cork | AB8: 12 | AC8: 2022 | AD8: 2025
A9: W-0008 | B9: Sable Dusk 008 | C9: Copperleaf Collective | D9: Moldova | E9: Mosel | F9: 2017 | G9: Red | H9: Cabernet Sauvignon | I9: 11.9 | J9: Dry | K9: Medium | L9: High | M9: Full | N9: black cherry, dark chocolate | O9: beef short ribs | P9: 290.21 | Q9: 204.31 | R9: =IFERROR((P9-Q9)/P9,0) -> 0.29599256 | S9: 96 | T9: 12 | U9: =P9*S9 -> 27860.16 | V9: In Stock | W9: Southern Wine Supply | X9: 3.6 | Y9: Yes | Z9: 1500 | AA9: Cork | AB9: 18 | AC9: 2026 | AD9: 2031
A10: W-0009 | B10: Golden Thistle 009 | C10: Silver Fern Cellars | D10: Hungary | E10: Margaret River | F10: 2000 | G10: Red | H10: Cabernet Sauvignon | I10: 9.9 | J10: Dry | K10: Medium | L10: Medium | M10: Full | N10: cedar, plum | O10: roast lamb | P10: 103.53 | Q10: 56.22 | R10: =IFERROR((P10-Q10)/P10,0) -> 0.45696899 | S10: 120 | T10: 12 | U10: =P10*S10 -> 12423.6 | V10: Backorder | W10: Global Cellars | X10: 4.6 | Y10: No | Z10: 750 | AA10: Screw cap | AB10: 8 | AC10: 2026 | AD10: 2031
A11: W-0010 | B11: Sunset Garden 010 | C11: Copperleaf Collective | D11: Japan | E11: Priorat | F11: 2006 | G11: Red | H11: Malbec | I11: 9.6 | J11: Dry | K11: Low | L11: High | M11: Full | N11: dark chocolate, raspberry | O11: roast lamb | P11: 263.59 | Q11: 135.87 | R11: =IFERROR((P11-Q11)/P11,0) -> 0.48454038 | S11: 0 | T11: 50 | U11: =P11*S11 -> 0 | V11: Out of Stock | W11: Heritage Imports | X11: 3.9 | Y11: No | Z11: 375 | AA11: Synthetic cork | AB11: 8 | AC11: 2025 | AD11: 2033
A12: W-0011 | B12: Midnight Lantern 011 | C12: Crown & Root Cellars | D12: Philippines | E12: Stellenbosch | F12: 2010 | G12: Red | H12: Merlot | I12: 10.6 | J12: Off-dry | K12: High | L12: Low | M12: Full | N12: tobacco, plum | O12: roast lamb | P12: 191.02 | Q12: 72.14 | R12: =IFERROR((P12-Q12)/P12,0) -> 0.62234321 | S12: 1 | T12: 24 | U12: =P12*S12 -> 191.02 | V12: Backorder | W12: Estate Direct | X12: 4.7 | Y12: No | Z12: 750 | AA12: Screw cap | AB12: 14 | AC12: 2024 | AD12: 2027
A13: W-0012 | B13: Cinder Compass 012 | C13: Marble Finch Winery | D13: Ethiopia | E13: Puglia | F13: 2016 | G13: Red | H13: Malbec | I13: 12.9 | J13: Off-dry | K13: Medium | L13: Medium | M13: Full | N13: tobacco, black pepper | O13: aged cheddar | P13: 399.13 | Q13: 161.29 | R13: =IFERROR((P13-Q13)/P13,0) -> 0.59589607 | S13: 96 | T13: 24 | U13: =P13*S13 -> 38316.48 | V13: In Stock | W13: Global Cellars | X13: 3.9 | Y13: Yes | Z13: 750 | AA13: Screw cap | AB13: 8 | AC13: 2026 | AD13: 2036
... A17: W-0016 | B17: Burnished Stone 016 | C17: Seven Valleys Cellars | D17: Colombia | E17: Martinborough | F17: 2006 | G17: Dessert | H17: Muscat | I17: 12.2 | J17: Sweet | K17: High | L17: Low | M17: Medium | N17: apricot, candied peach | O17: blue cheese | P17: 159.89 | Q17: 114.83 | R17: =IFERROR((P17-Q17)/P17,0) -> 0.28181875 | S17: 600 | T17: 12 | U17: =P17*S17 -> 95934 | V17: Backorder | W17: Southern Wine Supply | X17: 4.7 | Y17: No | Z17: 375 | AA17: Cork | AB17: 18 | AC17: 2026 | AD17: 2034
A18: W-0017 | B18: Wandering Vale 017 | C18: Northstar Estate | D18: Mauritius | E18: Sonoma County | F18: NV | G18: Sparkling | H18: Chardonnay | I18: 8.3 | J18: Dry | K18: Low | L18: Low | M18: Light | N18: brioche, green apple | O18: canapés | P18: 232.92 | Q18: 96.95 | R18: =IFERROR((P18-Q18)/P18,0) -> 0.58376267 | S18: 72 | T18: 24 | U18: =P18*S18 -> 16770.24 | V18: Backorder | W18: Southern Wine Supply | X18: 4.2 | Y18: Yes | Z18: 750 | AA18: Screw cap | AB18: 12 | AC18: 2024 | AD18: 2033
A19: W-0018 | B19: Moonlit Ridge 018 | C19: Marble Finch Winery | D19: Thailand | E19: Alsace | F19: 2012 | G19: Rosé | H19: Syrah | I19: 12 | J19: Dry | K19: High | L19: Low | M19: Light | N19: watermelon, strawberry | O19: charcuterie | P19: 225.38 | Q19: 83.6 | R19: =IFERROR((P19-Q19)/P19,0) -> 0.6290709 | S19: 350 | T19: 24 | U19: =P19*S19 -> 78883 | V19: Backorder | W19: Southern Wine Supply | X19: 3.4 | Y19: No | Z19: 750 | AA19: Screw cap | AB19: 16 | AC19: 2024 | AD19: 2031
A20: W-0019 | B20: Copper Canopy 019 | C20: Copperleaf Collective | D20: Serbia | E20: Barossa Valley | F20: 2000 | G20: White | H20: Albariño | I20: 15.5 | J20: Dry | K20: High | L20: Low | M20: Medium | N20: green apple, white peach | O20: seafood pasta | P20: 216.16 | Q20: 99.88 | R20: =IFERROR((P20-Q20)/P20,0) -> 0.53793486 | S20: 120 | T20: 12 | U20: =P20*S20 -> 25939.2 | V20: Backorder | W20: Heritage Imports | X20: 3.3 | Y20: No | Z20: 750 | AA20: Cork | AB20: 10 | AC20: 2022 | AD20: 2027
A21: W-0020 | B21: Ivory Lark 020 | C21: Copperleaf Collective | D21: Croatia | E21: Tuscany | F21: 2008 | G21: Red | H21: Malbec | I21: 9.8 | J21: Dry | K21: Medium | L21: Medium | M21: Full | N21: raspberry, dark chocolate | O21: aged cheddar | P21: 83.13 | Q21: 48.83 | R21: =IFERROR((P21-Q21)/P21,0) -> 0.41260676 | S21: 120 | T21: 24 | U21: =P21*S21 -> 9975.6 | V21: In Stock | W21: Heritage Imports | X21: 3.6 | Y21: No | Z21: 750 | AA21: Synthetic cork | AB21: 18 | AC21: 2022 | AD21: 2035
A22: W-0021 | B22: Hollow Vine 021 | C22: Seven Valleys Cellars | D22: Lebanon | E22: Marlborough | F22: 2006 | G22: White | H22: Sauvignon Blanc | I22: 11.2 | J22: Dry | K22: High | L22: Low | M22: Medium | N22: mineral, pear | O22: grilled fish | P22: 150.51 | Q22: 83.03 | R22: =IFERROR((P22-Q22)/P22,0) -> 0.4483423 | S22: 12 | T22: 6 | U22: =P22*S22 -> 1806.12 | V22: In Stock | W22: Heritage Imports | X22: 3.6 | Y22: No | Z22: 375 | AA22: Screw cap | AB22: 8 | AC22: 2024 | AD22: 2031
A23: W-0022 | B23: Quiet Grove 022 | C23: Marble Finch Winery | D23: Botswana | E23: Sicily | F23: 2002 | G23: Red | H23: Cabernet Sauvignon | I23: 7.9 | J23: Dry | K23: Low | L23: Medium | M23: Full | N23: black pepper, dark chocolate | O23: mushroom risotto | P23: 1638.09 | Q23: 760.16 | R23: =IFERROR((P23-Q23)/P23,0) -> 0.53594735 | S23: 36 | T23: 50 | U23: =P23*S23 -> 58971.24 | V23: In Stock | W23: Global Cellars | X23: 3.2 | Y23: No | Z23: 750 | AA23: Synthetic cork | AB23: 12 | AC23: 2023 | AD23: 2033
A24: W-0023 | B24: Ancient Bloom 023 | C24: Aster & Oak | D24: Romania | E24: Tuscany | F24: 2024 | G24: White | H24: Albariño | I24: 12.1 | J24: Off-dry | K24: Low | L24: Low | M24: Medium | N24: green apple, lime | O24: grilled fish | P24: 1648.44 | Q24: 669.26 | R24: =IFERROR((P24-Q24)/P24,0) -> 0.59400403 | S24: 12 | T24: 6 | U24: =P24*S24 -> 19781.28 | V24: Backorder | W24: Estate Direct | X24: 4.3 | Y24: No | Z24: 1500 | AA24: Cork | AB24: 18 | AC24: 2023 | AD24: 2033
A25: W-0024 | B25: Whispering Peak 024 | C25: Driftwood Ridge | D25: Cyprus | E25: Margaret River | F25: 2016 | G25: White | H25: Chardonnay | I25: 11.4 | J25: Dry | K25: Medium | L25: Low | M25: Medium | N25: lime, white peach | O25: grilled fish | P25: 231.19 | Q25: 93.3 | R25: =IFERROR((P25-Q25)/P25,0) -> 0.59643583 | S25: 36 | T25: 24 | U25: =P25*S25 -> 8322.84 | V25: In Stock | W25: Vine Trade NZ | X25: 4.1 | Y25: Yes | Z25: 750 | AA25: Cork | AB25: 14 | AC25: 2021 | AD25: 2028
A26: W-0025 | B26: Juniper Orchard 025 | C26: Northstar Estate | D26: Armenia | E26: Sicily | F26: 2023 | G26: White | H26: Pinot Gris | I26: 13.6 | J26: Off-dry | K26: Low | L26: Low | M26: Medium | N26: lime, mineral | O26: grilled fish | P26: 174.68 | Q26: 70.65 | R26: =IFERROR((P26-Q26)/P26,0) -> 0.59554614 | S26: 2 | T26: 12 | U26: =P26*S26 -> 349.36 | V26: In Stock | W26: Estate Direct | X26: 3.4 | Y26: Yes | Z26: 750 | AA26: Screw cap | AB26: 10 | AC26: 2028 | AD26: 2037
A27: W-0026 | B27: Hidden Chapel 026 | C27: Hearthstone Vintners | D27: Serbia | E27: Finger Lakes | F27: 2005 | G27: Red | H27: Cabernet Sauvignon | I27: 11 | J27: Dry | K27: High | L27: Medium | M27: Full | N27: black pepper, dark chocolate | O27: mushroom risotto | P27: 173.32 | Q27: 78.78 | R27: =IFERROR((P27-Q27)/P27,0) -> 0.54546504 | S27: 24 | T27: 6 | U27: =P27*S27 -> 4159.68 | V27: In Stock | W27: Heritage Imports | X27: 4.3 | Y27: Yes | Z27: 375 | AA27: Cork | AB27: 14 | AC27: 2022 | AD27: 2033
A28: W-0027 | B28: Velvet Bay 027 | C28: Copperleaf Collective | D28: Greece | E28: Rhône Valley | F28: 2024 | G28: Sparkling | H28: Pinot Noir | I28: 12.4 | J28: Dry | K28: Low | L28: Low | M28: Light | N28: almond, citrus | O28: fried calamari | P28: 138.51 | Q28: 66.52 | R28: =IFERROR((P28-Q28)/P28,0) -> 0.51974587 | S28: 36 | T28: 24 | U28: =P28*S28 -> 4986.36 | V28: In Stock | W28: Estate Direct | X28: 4.3 | Y28: No | Z28: 750 | AA28: Screw cap | AB28: 12 | AC28: 2024 | AD28: 2031
A29: W-0028 | B29: Autumn River 028 | C29: Hearthstone Vintners | D29: Greece | E29: Alsace | F29: 2001 | G29: White | H29: Chenin Blanc | I29: 11.4 | J29: Dry | K29: Low | L29: Low | M29: Medium | N29: white peach, lemon zest | O29: roast chicken | P29: 390.45 | Q29: 228.55 | R29: =IFERROR((P29-Q29)/P29,0) -> 0.41464976 | S29: 2 | T29: 36 | U29: =P29*S29 -> 780.9 | V29: In Stock | W29: Vine Trade NZ | X29: 4.9 | Y29: No | Z29: 750 | AA29: Synthetic cork | AB29: 18 | AC29: 2026 | AD29: 2032
A30: W-0029 | B30: Solstice Fjord 029 | C30: Hearthstone Vintners | D30: Morocco | E30: Tuscany | F30: 2011 | G30: Dessert | H30: Muscat | I30: 8 | J30: Sweet | K30: Medium | L30: Low | M30: Medium | N30: honey, apricot | O30: blue cheese | P30: 208.34 | Q30: 122.45 | R30: =IFERROR((P30-Q30)/P30,0) -> 0.41225881 | S30: 12 | T30: 6 | U30: =P30*S30 -> 2500.08 | V30: In Stock | W30: Estate Direct | X30: 3.7 | Y30: No | Z30: 750 | AA30: Cork | AB30: 10 | AC30: 2028 | AD30: 2035
... A80: W-0079 | B80: Copper Canopy 079 | C80: Crown & Root Cellars | D80: Slovenia | E80: Hunter Valley | F80: 2021 | G80: White | H80: Riesling | I80: 10.4 | J80: Dry | K80: Medium | L80: Low | M80: Medium | N80: lemon zest, mineral | O80: grilled fish | P80: 300.73 | Q80: 113.17 | R80: =IFERROR((P80-Q80)/P80,0) -> 0.62368237 | S80: 72 | T80: 24 | U80: =P80*S80 -> 21652.56 | V80: In Stock | W80: Estate Direct | X80: 3.3 | Y80: No | Z80: 375 | AA80: Cork | AB80: 12 | AC80: 2025 | AD80: 2028
A81: W-0080 | B81: Ivory Lark 080 | C81: Quiet Lantern Estate | D81: Turkey | E81: Burgundy | F81: NV | G81: Sparkling | H81: Pinot Meunier | I81: 12.6 | J81: Off-dry | K81: Low | L81: Low | M81: Light | N81: almond, green apple | O81: oysters | P81: 1301.08 | Q81: 834.96 | R81: =IFERROR((P81-Q81)/P81,0) -> 0.35825622 | S81: 12 | T81: 6 | U81: =P81*S81 -> 15612.96 | V81: In Stock | W81: Heritage Imports | X81: 4.1 | Y81: Yes | Z81: 1500 | AA81: Cork | AB81: 14 | AC81: 2024 | AD81: 2035
A82: W-0081 | B82: Hollow Vine 081 | C82: Northstar Estate | D82: Moldova | E82: Nelson | F82: 2003 | G82: Red | H82: Nebbiolo | I82: 12.2 | J82: Dry | K82: High | L82: High | M82: Full | N82: raspberry, dark chocolate | O82: mushroom risotto | P82: 224.58 | Q82: 126.8 | R82: =IFERROR((P82-Q82)/P82,0) -> 0.43539051 | S82: 350 | T82: 50 | U82: =P82*S82 -> 78603 | V82: In Stock | W82: Estate Direct | X82: 4.3 | Y82: No | Z82: 750 | AA82: Cork | AB82: 10 | AC82: 2026 | AD82: 2037
A83: W-0082 | B83: Quiet Grove 082 | C83: Thorn & Tide Wines | D83: North Macedonia | E83: Willamette Valley | F83: 2000 | G83: Rosé | H83: Pinot Noir | I83: 8.8 | J83: Off-dry | K83: High | L83: Low | M83: Light | N83: rose petal, watermelon | O83: summer salads | P83: 215.17 | Q83: 95.91 | R83: =IFERROR((P83-Q83)/P83,0) -> 0.55425942 | S83: 72 | T83: 12 | U83: =P83*S83 -> 15492.24 | V83: In Stock | W83: Global Cellars | X83: 4 | Y83: No | Z83: 750 | AA83: Screw cap | AB83: 16 | AC83: 2022 | AD83: 2027
A84: W-0083 | B84: Ancient Bloom 083 | C84: Marble Finch Winery | D84: Indonesia | E84: Loire Valley | F84: 2015 | G84: Red | H84: Cabernet Sauvignon | I84: 8.3 | J84: Dry | K84: Low | L84: High | M84: Full | N84: tobacco, plum | O84: roast lamb | P84: 406.53 | Q84: 191.73 | R84: =IFERROR((P84-Q84)/P84,0) -> 0.52837429 | S84: 2 | T84: 6 | U84: =P84*S84 -> 813.06 | V84: In Stock | W84: Heritage Imports | X84: 3.9 | Y84: Yes | Z84: 1500 | AA84: Synthetic cork | AB84: 14 | AC84: 2021 | AD84: 2024
A85: W-0084 | B85: Whispering Peak 084 | C85: Quiet Lantern Estate | D85: Kenya | E85: Central Valley | F85: 2013 | G85: White | H85: Chenin Blanc | I85: 12.2 | J85: Dry | K85: High | L85: Low | M85: Medium | N85: green apple, lime | O85: grilled fish | P85: 211.4 | Q85: 133.14 | R85: =IFERROR((P85-Q85)/P85,0) -> 0.37019868 | S85: 0 | T85: 24 | U85: =P85*S85 -> 0 | V85: Out of Stock | W85: Southern Wine Supply | X85: 3.7 | Y85: No | Z85: 375 | AA85: Cork | AB85: 10 | AC85: 2028 | AD85: 2031
A86: W-0085 | B86: Juniper Orchard 085 | C86: Silver Fern Cellars | D86: Slovenia | E86: Veneto | F86: 2020 | G86: Red | H86: Malbec | I86: 7.7 | J86: Dry | K86: High | L86: Medium | M86: Full | N86: black pepper, tobacco | O86: mushroom risotto | P86: 176.6 | Q86: 115.7 | R86: =IFERROR((P86-Q86)/P86,0) -> 0.34484711 | S86: 5 | T86: 12 | U86: =P86*S86 -> 883 | V86: In Stock | W86: Vine Trade NZ | X86: 4.8 | Y86: No | Z86: 750 | AA86: Cork | AB86: 14 | AC86: 2023 | AD86: 2031
A87: W-0086 | B87: Hidden Chapel 086 | C87: Crown & Root Cellars | D87: Zimbabwe | E87: Champagne | F87: 2023 | G87: Red | H87: Cabernet Sauvignon | I87: 15.1 | J87: Dry | K87: High | L87: Low | M87: Full | N87: black cherry, cedar | O87: roast lamb | P87: 127.73 | Q87: 67.98 | R87: =IFERROR((P87-Q87)/P87,0) -> 0.46778361 | S87: 5 | T87: 12 | U87: =P87*S87 -> 638.65 | V87: In Stock | W87: Vine Trade NZ | X87: 3.7 | Y87: No | Z87: 375 | AA87: Synthetic cork | AB87: 12 | AC87: 2026 | AD87: 2030
A88: W-0087 | B88: Velvet Bay 087 | C88: Marble Finch Winery | D88: Uganda | E88: Maipo Valley | F88: 2006 | G88: Rosé | H88: Grenache | I88: 13.2 | J88: Dry | K88: Medium | L88: Low | M88: Light | N88: watermelon, strawberry | O88: grilled prawns | P88: 164.95 | Q88: 98.17 | R88: =IFERROR((P88-Q88)/P88,0) -> 0.40484995 | S88: 12 | T88: 36 | U88: =P88*S88 -> 1979.4 | V88: In Stock | W88: Global Cellars | X88: 4.4 | Y88: No | Z88: 750 | AA88: Screw cap | AB88: 8 | AC88: 2028 | AD88: 2034
A89: W-0088 | B89: Autumn River 088 | C89: Bellwether Vineyards | D89: Mauritius | E89: Tuscany | F89: 2011 | G89: Red | H89: Malbec | I89: 15.6 | J89: Off-dry | K89: Low | L89: Low | M89: Full | N89: dark chocolate, black cherry | O89: aged cheddar | P89: 100.3 | Q89: 70.62 | R89: =IFERROR((P89-Q89)/P89,0) -> 0.29591226 | S89: 36 | T89: 12 | U89: =P89*S89 -> 3610.8 | V89: In Stock | W89: Estate Direct | X89: 4.8 | Y89: No | Z89: 750 | AA89: Cork | AB89: 14 | AC89: 2025 | AD89: 2034
A90: W-0089 | B90: Solstice Fjord 089 | C90: Marble Finch Winery | D90: Vietnam | E90: Champagne | F90: 2002 | G90: Red | H90: Tempranillo | I90: 14 | J90: Dry | K90: Low | L90: High | M90: Full | N90: black pepper, raspberry | O90: mushroom risotto | P90: 256.1 | Q90: 114.8 | R90: =IFERROR((P90-Q90)/P90,0) -> 0.5517376 | S90: 350 | T90: 36 | U90: =P90*S90 -> 89635 | V90: In Stock | W90: Southern Wine Supply | X90: 3.6 | Y90: No | Z90: 750 | AA90: Synthetic cork | AB90: 8 | AC90: 2021 | AD90: 2027
A91: W-0090 | B91: Amber Crest 090 | C91: Seven Valleys Cellars | D91: Jordan | E91: Highland Vineyards | F91: 2004 | G91: White | H91: Chenin Blanc | I91: 10.6 | J91: Dry | K91: Medium | L91: Low | M91: Medium | N91: lime, lemon zest | O91: roast chicken | P91: 163.84 | Q91: 62.42 | R91: =IFERROR((P91-Q91)/P91,0) -> 0.61901855 | S91: 1000 | T91: 24 | U91: =P91*S91 -> 163840 | V91: In Stock | W91: Estate Direct | X91: 4.9 | Y91: No | Z91: 750 | AA91: Synthetic cork | AB91: 16 | AC91: 2025 | AD91: 2035
A92: W-0091 | B92: Crimson Cove 091 | C92: Crown & Root Cellars | D92: Greece | E92: Rhône Valley | F92: 2007 | G92: Red | H92: Tempranillo | I92: 15.2 | J92: Dry | K92: High | L92: Low | M92: Full | N92: black cherry, plum | O92: mushroom risotto | P92: 73.04 | Q92: 32.71 | R92: =IFERROR((P92-Q92)/P92,0) -> 0.5521632 | S92: 36 | T92: 12 | U92: =P92*S92 -> 2629.44 | V92: In Stock | W92: Estate Direct | X92: 3.4 | Y92: No | Z92: 750 | AA92: Cork | AB92: 16 | AC92: 2021 | AD92: 2027
...

Sheet Country Summary
A1: Country of Origin | B1: Number of Wines | C1: Share of Inventory
A2: Tunisia | B2: =COUNTIF('Wine Inventory'!$D$2:$D$251,A2) -> 5 | C2: =B2/SUM($B$2:$B$46) -> 0.02
A3: Greece | B3: =COUNTIF('Wine Inventory'!$D$2:$D$251,A3) -> 5 | C3: =B3/SUM($B$2:$B$46) -> 0.02
A4: Romania | B4: =COUNTIF('Wine Inventory'!$D$2:$D$251,A4) -> 6 | C4: =B4/SUM($B$2:$B$46) -> 0.024
A5: Mauritius | B5: =COUNTIF('Wine Inventory'!$D$2:$D$251,A5) -> 5 | C5: =B5/SUM($B$2:$B$46) -> 0.02
A6: Namibia | B6: =COUNTIF('Wine Inventory'!$D$2:$D$251,A6) -> 5 | C6: =B6/SUM($B$2:$B$46) -> 0.02
A7: Morocco | B7: =COUNTIF('Wine Inventory'!$D$2:$D$251,A7) -> 5 | C7: =B7/SUM($B$2:$B$46) -> 0.02
A8: Philippines | B8: =COUNTIF('Wine Inventory'!$D$2:$D$251,A8) -> 3 | C8: =B8/SUM($B$2:$B$46) -> 0.012
A9: Georgia | B9: =COUNTIF('Wine Inventory'!$D$2:$D$251,A9) -> 6 | C9: =B9/SUM($B$2:$B$46) -> 0.024
A10: Thailand | B10: =COUNTIF('Wine Inventory'!$D$2:$D$251,A10) -> 6 | C10: =B10/SUM($B$2:$B$46) -> 0.024
A11: Turkey | B11: =COUNTIF('Wine Inventory'!$D$2:$D$251,A11) -> 3 | C11: =B11/SUM($B$2:$B$46) -> 0.012
A12: Botswana | B12: =COUNTIF('Wine Inventory'!$D$2:$D$251,A12) -> 8 | C12: =B12/SUM($B$2:$B$46) -> 0.032
A13: Japan | B13: =COUNTIF('Wine Inventory'!$D$2:$D$251,A13) -> 8 | C13: =B13/SUM($B$2:$B$46) -> 0.032
... A46: Vietnam | B46: =COUNTIF('Wine Inventory'!$D$2:$D$251,A46) -> 6 | C46: =B46/SUM($B$2:$B$46) -> 0.024
A47: Total | B47: =SUM(B2:B46) -> 250
